Workbook
Name x: Second_par!$C$26:$C$305
Name x: Sum_to_zero!$C$26:$C$277
Name x: First_par!$C$26:$C$277
Name Y: Second_par!$E$6:$E$305
Name Y: Sum_to_zero!$D$6:$D$277
Name Y: First_par!$D$6:$D$277

Sheet First_par
C2: y= Andamento delle vendite di un bene (in migliaia di Euro durante il periodo I trim 2001 - 4 trim 2005)
D4: PRIMA PARAMETRIZZAZIONE (SENZA L'INTERCETTA GENERALE)
B5: Trimestri | C5: y | D5: Trend | E5: Spring | F5: Summer | G5: Autumn | H5: Winter | I5: Valori teorici | J5: Serie detrendizzata | K5: Serie destagionalizzata | L5: Serie detrendizzata e destagionalizzata (residui) | M5: e_t-e_t-1
B6: trim 1 2021 | C6: 254 | D6: 1 | E6: 1 | F6: 0 | G6: 0 | H6: 0 | I6: =MMULT(D6:H6,K$33:K$37) -> 259.51 | J6: =C6-D6*K$33 -> 248.89375 | K6: =C6-MMULT(E6:H6,K$34:K$37) -> -0.40375 | L6: =C6-I6 -> -5.51
B7: trim 2 2021 | C7: 292.4 | D7: 2 | E7: 0 | F7: 1 | G7: 0 | H7: 0 | I7: =MMULT(D7:H7,K$33:K$37) -> 301.83 | J7: =C7-D7*K$33 -> 282.1875 | K7: =C7-MMULT(E7:H7,K$34:K$37) -> 0.7825 | L7: =C7-I7 -> -9.43 | M7: =L7-L6 -> -3.92
B8: trim 3 2021 | C8: 297.8 | D8: 3 | E8: 0 | F8: 0 | G8: 1 | H8: 0 | I8: =MMULT(D8:H8,K$33:K$37) -> 303.75 | J8: =C8-D8*K$33 -> 282.48125 | K8: =C8-MMULT(E8:H8,K$34:K$37) -> 9.36875 | L8: =C8-I8 -> -5.95 | M8: =L8-L7 -> 3.48
B9: trim 4 2021 | C9: 330.3 | D9: 4 | E9: 0 | F9: 0 | G9: 0 | H9: 1 | I9: =MMULT(D9:H9,K$33:K$37) -> 331.43 | J9: =C9-D9*K$33 -> 309.875 | K9: =C9-MMULT(E9:H9,K$34:K$37) -> 19.295 | L9: =C9-I9 -> -1.13 | M9: =L9-L8 -> 4.82
B10: trim 1 2022 | C10: 291.1 | D10: 5 | E10: 1 | F10: 0 | G10: 0 | H10: 0 | I10: =MMULT(D10:H10,K$33:K$37) -> 279.935 | J10: =C10-D10*K$33 -> 265.56875 | K10: =C10-MMULT(E10:H10,K$34:K$37) -> 36.69625 | L10: =C10-I10 -> 11.165 | M10: =L10-L9 -> 12.295
B11: trim 2 2022 | C11: 327.6 | D11: 6 | E11: 0 | F11: 1 | G11: 0 | H11: 0 | I11: =MMULT(D11:H11,K$33:K$37) -> 322.255 | J11: =C11-D11*K$33 -> 296.9625 | K11: =C11-MMULT(E11:H11,K$34:K$37) -> 35.9825 | L11: =C11-I11 -> 5.345 | M11: =L11-L10 -> -5.82
B12: trim 3 2022 | C12: 321.2 | D12: 7 | E12: 0 | F12: 0 | G12: 1 | H12: 0 | I12: =MMULT(D12:H12,K$33:K$37) -> 324.175 | J12: =C12-D12*K$33 -> 285.45625 | K12: =C12-MMULT(E12:H12,K$34:K$37) -> 32.76875 | L12: =C12-I12 -> -2.975 | M12: =L12-L11 -> -8.32
B13: trim 4 2022 | C13: 354.3 | D13: 8 | E13: 0 | F13: 0 | G13: 0 | H13: 1 | I13: =MMULT(D13:H13,K$33:K$37) -> 351.855 | J13: =C13-D13*K$33 -> 313.45 | K13: =C13-MMULT(E13:H13,K$34:K$37) -> 43.295 | L13: =C13-I13 -> 2.445 | M13: =L13-L12 -> 5.42
B14: trim 1 2023 | C14: 304.6 | D14: 9 | E14: 1 | F14: 0 | G14: 0 | H14: 0 | I14: =MMULT(D14:H14,K$33:K$37) -> 300.36 | J14: =C14-D14*K$33 -> 258.64375 | K14: =C14-MMULT(E14:H14,K$34:K$37) -> 50.19625 | L14: =C14-I14 -> 4.24 | M14: =L14-L13 -> 1.795
B15: trim 2 2023 | C15: 348.4 | D15: 10 | E15: 0 | F15: 1 | G15: 0 | H15: 0 | I15: =MMULT(D15:H15,K$33:K$37) -> 342.68 | J15: =C15-D15*K$33 -> 297.3375 | K15: =C15-MMULT(E15:H15,K$34:K$37) -> 56.7825 | L15: =C15-I15 -> 5.72 | M15: =L15-L14 -> 1.48
B16: trim 3 2023 | C16: 350.8 | D16: 11 | E16: 0 | F16: 0 | G16: 1 | H16: 0 | I16: =MMULT(D16:H16,K$33:K$37) -> 344.6 | J16: =C16-D16*K$33 -> 294.63125 | K16: =C16-MMULT(E16:H16,K$34:K$37) -> 62.36875 | L16: =C16-I16 -> 6.2 | M16: =L16-L15 -> 0.48
B17: trim 4 2023 | C17: 374.2 | D17: 12 | E17: 0 | F17: 0 | G17: 0 | H17: 1 | I17: =MMULT(D17:H17,K$33:K$37) -> 372.28 | J17: =C17-D17*K$33 -> 312.925 | K17: =C17-MMULT(E17:H17,K$34:K$37) -> 63.195 | L17: =C17-I17 -> 1.92 | M17: =L17-L16 -> -4.28
B18: trim 1 2024 | C18: 319.5 | D18: 13 | E18: 1 | F18: 0 | G18: 0 | H18: 0 | I18: =MMULT(D18:H18,K$33:K$37) -> 320.785 | J18: =C18-D18*K$33 -> 253.11875 | K18: =C18-MMULT(E18:H18,K$34:K$37) -> 65.09625 | L18: =C18-I18 -> -1.285 | M18: =L18-L17 -> -3.205
... B25: trim 4 2025 | C25: 407.4 | D25: 20 | E25: 0 | F25: 0 | G25: 0 | H25: 1 | I25: =MMULT(D25:H25,K$33:K$37) -> 413.13 | J25: =C25-D25*K$33 -> 305.275 | K25: =C25-MMULT(E25:H25,K$34:K$37) -> 96.395 | L25: =C25-I25 -> -5.73 | M25: =L25-L24 -> -4.08
B26: trim 1 2026
B27: trim 2 2026
B28: trim 3 2026
B29: trim 4 2026
C31: Output della funzione REGR.LIN
K32: Coeff. stimati
C33: {=LINEST(C6:C25,D6:H25,0,1)} -> 311.005 | D33: 288.43125 | E33: 291.6175 | F33: 254.40375 | G33: 5.10625 | J33: Trend | K33: =INDEX(C$33:G$33,1,M33) -> 5.10625 | M33: 5
C34: 3.9694859 | D34: 3.7979521 | E34: 3.6342704 | F34: 3.479549 | G34: 0.24068544 | H34: Coerff. stimati | J34: Primavera | K34: =INDEX(C$33:G$33,1,M34) -> 254.40375 | M34: 4
C35: 0.99976256 | D35: 6.0889134 | E35: #N/A | F35: #N/A | G35: #N/A | J35: Estate | K35: =INDEX(C$33:G$33,1,M35) -> 291.6175 | M35: 3
C36: 12631.865 | D36: 15 | E36: #N/A | F36: #N/A | G36: #N/A | J36: Autunno | K36: =INDEX(C$33:G$33,1,M36) -> 288.43125 | M36: 2
C37: 2341623.6 | D37: 556.123 | E37: #N/A | F37: #N/A | G37: #N/A | J37: Inverno | K37: =INDEX(C$33:G$33,1,M37) -> 311.005 | M37: 1
H39: RELAZIONI TRA LE DUE PARAMETRIZZAZIONI
I41: Parametrizzazione senza intercetta | K41: Parametrizzazione senza livello associato all'inverno
I43: Trend | J43: =K33 -> 5.10625 | K43: Intercetta | L43: =Second_par!J33 -> 311.005
I44: Primavera | J44: =K34 -> 254.40375 | K44: Trend | L44: =Second_par!J34 -> 5.10625
I45: Estate | J45: =K35 -> 291.6175 | K45: Primavera | L45: =Second_par!J35 -> -56.60125
I46: Autunno | J46: =K36 -> 288.43125 | K46: Estate | L46: =Second_par!J36 -> -19.3875
I47: Inverno | J47: =K37 -> 311.005 | K47: Autunno | L47: =Second_par!J37 -> -22.57375
G49: Relazione tra le due parametrizzazioni | J49: =J44-J$47 -> -56.60125
J50: =J45-J$47 -> -19.3875
J51: =J46-J$47 -> -22.57375
D55: Test sulla presenza del trend
D56: Occorre testare che il coefficiente di regressione parziale associato al trend sia significativamente diverso da 0
...

Sheet Second_par
C2: y= Andamento delle vendite di un bene (in migliaia di Euro durante il periodo I trim 2001 - 4 trim 2005)
C4: SECONDA PARAMETRIZZAZIONE (SENZA IL LIVELLO ASSOCIATO ALL'INVERNO)
B5: Trimestri | C5: y | D5: Intercetta | E5: Spring | F5: Summer | G5: Autumn | H5: Winter | I5: Valori teorici | J5: Serie detrendizzata | K5: Serie destagionalizzata | L5: Serie detrendizzata e destagionalizzata (residui)
B6: trim 1 2021 | C6: 254 | D6: 1 | E6: 1 | F6: 1 | G6: 0 | H6: 0 | I6: =MMULT(D6:H6,J$33:J$37) -> 259.51 | J6: =C6-E6*J$34 -> 248.89375 | K6: =C6-D6*J$33-MMULT(F6:H6,J$35:J$37) -> -0.40375 | L6: =C6-I6 -> -5.51
B7: trim 2 2021 | C7: 292.4 | D7: 1 | E7: 2 | F7: 0 | G7: 1 | H7: 0 | I7: =MMULT(D7:H7,J$33:J$37) -> 301.83 | J7: =C7-E7*J$34 -> 282.1875 | K7: =C7-D7*J$33-MMULT(F7:H7,J$35:J$37) -> 0.7825 | L7: =C7-I7 -> -9.43
B8: trim 3 2021 | C8: 297.8 | D8: 1 | E8: 3 | F8: 0 | G8: 0 | H8: 1 | I8: =MMULT(D8:H8,J$33:J$37) -> 303.75 | J8: =C8-E8*J$34 -> 282.48125 | K8: =C8-D8*J$33-MMULT(F8:H8,J$35:J$37) -> 9.36875 | L8: =C8-I8 -> -5.95
B9: trim 4 2021 | C9: 330.3 | D9: 1 | E9: 4 | F9: 0 | G9: 0 | H9: 0 | I9: =MMULT(D9:H9,J$33:J$37) -> 331.43 | J9: =C9-E9*J$34 -> 309.875 | K9: =C9-D9*J$33-MMULT(F9:H9,J$35:J$37) -> 19.295 | L9: =C9-I9 -> -1.13
B10: trim 1 2022 | C10: 291.1 | D10: 1 | E10: 5 | F10: 1 | G10: 0 | H10: 0 | I10: =MMULT(D10:H10,J$33:J$37) -> 279.935 | J10: =C10-E10*J$34 -> 265.56875 | K10: =C10-D10*J$33-MMULT(F10:H10,J$35:J$37) -> 36.69625 | L10: =C10-I10 -> 11.165
B11: trim 2 2022 | C11: 327.6 | D11: 1 | E11: 6 | F11: 0 | G11: 1 | H11: 0 | I11: =MMULT(D11:H11,J$33:J$37) -> 322.255 | J11: =C11-E11*J$34 -> 296.9625 | K11: =C11-D11*J$33-MMULT(F11:H11,J$35:J$37) -> 35.9825 | L11: =C11-I11 -> 5.345
B12: trim 3 2022 | C12: 321.2 | D12: 1 | E12: 7 | F12: 0 | G12: 0 | H12: 1 | I12: =MMULT(D12:H12,J$33:J$37) -> 324.175 | J12: =C12-E12*J$34 -> 285.45625 | K12: =C12-D12*J$33-MMULT(F12:H12,J$35:J$37) -> 32.76875 | L12: =C12-I12 -> -2.975
B13: trim 4 2022 | C13: 354.3 | D13: 1 | E13: 8 | F13: 0 | G13: 0 | H13: 0 | I13: =MMULT(D13:H13,J$33:J$37) -> 351.855 | J13: =C13-E13*J$34 -> 313.45 | K13: =C13-D13*J$33-MMULT(F13:H13,J$35:J$37) -> 43.295 | L13: =C13-I13 -> 2.445
B14: trim 1 2023 | C14: 304.6 | D14: 1 | E14: 9 | F14: 1 | G14: 0 | H14: 0 | I14: =MMULT(D14:H14,J$33:J$37) -> 300.36 | J14: =C14-E14*J$34 -> 258.64375 | K14: =C14-D14*J$33-MMULT(F14:H14,J$35:J$37) -> 50.19625 | L14: =C14-I14 -> 4.24
B15: trim 2 2023 | C15: 348.4 | D15: 1 | E15: 10 | F15: 0 | G15: 1 | H15: 0 | I15: =MMULT(D15:H15,J$33:J$37) -> 342.68 | J15: =C15-E15*J$34 -> 297.3375 | K15: =C15-D15*J$33-MMULT(F15:H15,J$35:J$37) -> 56.7825 | L15: =C15-I15 -> 5.72
B16: trim 3 2023 | C16: 350.8 | D16: 1 | E16: 11 | F16: 0 | G16: 0 | H16: 1 | I16: =MMULT(D16:H16,J$33:J$37) -> 344.6 | J16: =C16-E16*J$34 -> 294.63125 | K16: =C16-D16*J$33-MMULT(F16:H16,J$35:J$37) -> 62.36875 | L16: =C16-I16 -> 6.2
B17: trim 4 2023 | C17: 374.2 | D17: 1 | E17: 12 | F17: 0 | G17: 0 | H17: 0 | I17: =MMULT(D17:H17,J$33:J$37) -> 372.28 | J17: =C17-E17*J$34 -> 312.925 | K17: =C17-D17*J$33-MMULT(F17:H17,J$35:J$37) -> 63.195 | L17: =C17-I17 -> 1.92
... B25: trim 4 2025 | C25: 407.4 | D25: 1 | E25: 20 | F25: 0 | G25: 0 | H25: 0 | I25: =MMULT(D25:H25,J$33:J$37) -> 413.13 | J25: =C25-E25*J$34 -> 305.275 | K25: =C25-D25*J$33-MMULT(F25:H25,J$35:J$37) -> 96.395 | L25: =C25-I25 -> -5.73
B26: trim 1 2026
B27: trim 2 2026
B28: trim 3 2026
B29: trim 4 2026
C31: Output della funzione REGR.LIN
J32: Coefficienti stimati
C33: {=LINEST(C6:C25,E6:H25,1,1)} -> -22.57375 | D33: -19.3875 | E33: -56.60125 | F33: 5.10625 | G33: 311.005 | I33: Intercetta | J33: =INDEX(C$33:G$33,1,M33) -> 311.005 | M33: 5
C34: 3.8584811 | D34: 3.880936 | E34: 3.918075 | F34: 0.24068544 | G34: 3.9694859 | I34: Trend | J34: =INDEX(C$33:G$33,1,M34) -> 5.10625 | M34: 4
C35: 0.98173753 | D35: 6.0889134 | E35: #N/A | F35: #N/A | G35: #N/A | I35: Primavera | J35: =INDEX(C$33:G$33,1,M35) -> -56.60125 | M35: 3
C36: 201.58919 | D36: 15 | E36: #N/A | F36: #N/A | G36: #N/A | I36: Estate | J36: =INDEX(C$33:G$33,1,M36) -> -19.3875 | M36: 2
C37: 29895.569 | D37: 556.123 | E37: #N/A | F37: #N/A | G37: #N/A | I37: Autunno | J37: =INDEX(C$33:G$33,1,M37) -> -22.57375 | M37: 1
C42: Test sulla presenza della stagionalità
C43: Occorre testare l'ipotesi che i coefficienti relativi alle stagioni non siano significativi H_0:beta_primavera=beta_estate=beta_autunno=0
C45: Primo modo per calcolare il test: confronto tra la somma dei quadrati dei residui con e senza le variabili dummy associate alle stagioni
C47: Regressione lineare in un modello che non contiene gli effetti stagionali (modello ridotto y= intercetta +trend+epsilon)
C48: {=LINEST(C6:C25,E6:E25,1,1)} -> 5.7326316 | D48: 279.78737
C49: 0.84751117 | D49: 10.152462
C50: 0.71765924 | D50: 21.855274
C51: 45.75275 | D51: 18
C52: 21853.938 | D52: 8597.7539
B55: Somma dei quadrati dei residui del modello ridotto (e'_re_r) | I55: =D52 -> 8597.7539 | K55: q= | L55: 3
B56: Somma dei quadrati dei residui del modello completo (e'e) | I56: =D37 -> 556.123 | K56: n-k= | L56: =D36 -> 15
L61: Numeratore F | O61: =(I55-I56)/3 -> 2680.5436
L63: Denominatore F | O63: =I56/L56 -> 37.074867
...

Sheet Sum_to_zero
C2: y= Andamento delle vendite di un bene (in migliaia di Euro durante il periodo I trim 2001 - 4 trim 2005)
D4: SCOMPOSIZIONE DELLA SERIE STORICA CON IL VINCOLO DI SOMMA A ZERO DEI COEFFICIENTI STAGIONALI
B5: Trimestri | C5: y | D5: Trend | E5: Spring | F5: Summer | G5: Autumn | H5: Winter | I5: Valori teorici | J5: Stima del trend | K5: Serie detrendizzata | L5: Componente stagionale a somma zero | M5: Serie destagionalizzata con il vincolo di somma a zero dei coefficienti stagionali | N5: Serie detrendizzata e destagionalizzata (residui) | O5: Serie detrendizzata e destagionalizzata
B6: trim 1 2021 | C6: 254 | D6: 1 | E6: 1 | F6: 0 | G6: 0 | H6: 0 | I6: =MMULT(D6:H6,K$33:K$37) -> 259.51 | J6: =K$38+K$33*D6 -> 291.47062 | K6: =C6-D6*K$33-K$38 -> -37.470625 | L6: =MMULT(E6:H6,L$34:L$37) -> -31.960625 | M6: =C6-MMULT(E6:H6,L$34:L$37) -> 285.96063 | N6: =C6-I6 -> -5.51 | O6: =C6-J6-L6 -> -5.51
B7: trim 2 2021 | C7: 292.4 | D7: 2 | E7: 0 | F7: 1 | G7: 0 | H7: 0 | I7: =MMULT(D7:H7,K$33:K$37) -> 301.83 | J7: =K$38+K$33*D7 -> 296.57687 | K7: =C7-D7*K$33-K$38 -> -4.176875 | L7: =MMULT(E7:H7,L$34:L$37) -> 5.253125 | M7: =C7-MMULT(E7:H7,L$34:L$37) -> 287.14687 | N7: =C7-I7 -> -9.43 | O7: =C7-J7-L7 -> -9.43
B8: trim 3 2021 | C8: 297.8 | D8: 3 | E8: 0 | F8: 0 | G8: 1 | H8: 0 | I8: =MMULT(D8:H8,K$33:K$37) -> 303.75 | J8: =K$38+K$33*D8 -> 301.68312 | K8: =C8-D8*K$33-K$38 -> -3.883125 | L8: =MMULT(E8:H8,L$34:L$37) -> 2.066875 | M8: =C8-MMULT(E8:H8,L$34:L$37) -> 295.73312 | N8: =C8-I8 -> -5.95 | O8: =C8-J8-L8 -> -5.95
B9: trim 4 2021 | C9: 330.3 | D9: 4 | E9: 0 | F9: 0 | G9: 0 | H9: 1 | I9: =MMULT(D9:H9,K$33:K$37) -> 331.43 | J9: =K$38+K$33*D9 -> 306.78937 | K9: =C9-D9*K$33-K$38 -> 23.510625 | L9: =MMULT(E9:H9,L$34:L$37) -> 24.640625 | M9: =C9-MMULT(E9:H9,L$34:L$37) -> 305.65938 | N9: =C9-I9 -> -1.13 | O9: =C9-J9-L9 -> -1.13
B10: trim 1 2022 | C10: 291.1 | D10: 5 | E10: 1 | F10: 0 | G10: 0 | H10: 0 | I10: =MMULT(D10:H10,K$33:K$37) -> 279.935 | J10: =K$38+K$33*D10 -> 311.89562 | K10: =C10-D10*K$33-K$38 -> -20.795625 | L10: =MMULT(E10:H10,L$34:L$37) -> -31.960625 | M10: =C10-MMULT(E10:H10,L$34:L$37) -> 323.06063 | N10: =C10-I10 -> 11.165 | O10: =C10-J10-L10 -> 11.165
B11: trim 2 2022 | C11: 327.6 | D11: 6 | E11: 0 | F11: 1 | G11: 0 | H11: 0 | I11: =MMULT(D11:H11,K$33:K$37) -> 322.255 | J11: =K$38+K$33*D11 -> 317.00187 | K11: =C11-D11*K$33-K$38 -> 10.598125 | L11: =MMULT(E11:H11,L$34:L$37) -> 5.253125 | M11: =C11-MMULT(E11:H11,L$34:L$37) -> 322.34687 | N11: =C11-I11 -> 5.345 | O11: =C11-J11-L11 -> 5.345
B12: trim 3 2022 | C12: 321.2 | D12: 7 | E12: 0 | F12: 0 | G12: 1 | H12: 0 | I12: =MMULT(D12:H12,K$33:K$37) -> 324.175 | J12: =K$38+K$33*D12 -> 322.10812 | K12: =C12-D12*K$33-K$38 -> -0.908125 | L12: =MMULT(E12:H12,L$34:L$37) -> 2.066875 | M12: =C12-MMULT(E12:H12,L$34:L$37) -> 319.13312 | N12: =C12-I12 -> -2.975 | O12: =C12-J12-L12 -> -2.975
B13: trim 4 2022 | C13: 354.3 | D13: 8 | E13: 0 | F13: 0 | G13: 0 | H13: 1 | I13: =MMULT(D13:H13,K$33:K$37) -> 351.855 | J13: =K$38+K$33*D13 -> 327.21437 | K13: =C13-D13*K$33-K$38 -> 27.085625 | L13: =MMULT(E13:H13,L$34:L$37) -> 24.640625 | M13: =C13-MMULT(E13:H13,L$34:L$37) -> 329.65938 | N13: =C13-I13 -> 2.445 | O13: =C13-J13-L13 -> 2.445
B14: trim 1 2023 | C14: 304.6 | D14: 9 | E14: 1 | F14: 0 | G14: 0 | H14: 0 | I14: =MMULT(D14:H14,K$33:K$37) -> 300.36 | J14: =K$38+K$33*D14 -> 332.32062 | K14: =C14-D14*K$33-K$38 -> -27.720625 | L14: =MMULT(E14:H14,L$34:L$37) -> -31.960625 | M14: =C14-MMULT(E14:H14,L$34:L$37) -> 336.56063 | N14: =C14-I14 -> 4.24 | O14: =C14-J14-L14 -> 4.24
B15: trim 2 2023 | C15: 348.4 | D15: 10 | E15: 0 | F15: 1 | G15: 0 | H15: 0 | I15: =MMULT(D15:H15,K$33:K$37) -> 342.68 | J15: =K$38+K$33*D15 -> 337.42687 | K15: =C15-D15*K$33-K$38 -> 10.973125 | L15: =MMULT(E15:H15,L$34:L$37) -> 5.253125 | M15: =C15-MMULT(E15:H15,L$34:L$37) -> 343.14687 | N15: =C15-I15 -> 5.72 | O15: =C15-J15-L15 -> 5.72
B16: trim 3 2023 | C16: 350.8 | D16: 11 | E16: 0 | F16: 0 | G16: 1 | H16: 0 | I16: =MMULT(D16:H16,K$33:K$37) -> 344.6 | J16: =K$38+K$33*D16 -> 342.53312 | K16: =C16-D16*K$33-K$38 -> 8.266875 | L16: =MMULT(E16:H16,L$34:L$37) -> 2.066875 | M16: =C16-MMULT(E16:H16,L$34:L$37) -> 348.73312 | N16: =C16-I16 -> 6.2 | O16: =C16-J16-L16 -> 6.2
B17: trim 4 2023 | C17: 374.2 | D17: 12 | E17: 0 | F17: 0 | G17: 0 | H17: 1 | I17: =MMULT(D17:H17,K$33:K$37) -> 372.28 | J17: =K$38+K$33*D17 -> 347.63937 | K17: =C17-D17*K$33-K$38 -> 26.560625 | L17: =MMULT(E17:H17,L$34:L$37) -> 24.640625 | M17: =C17-MMULT(E17:H17,L$34:L$37) -> 349.55938 | N17: =C17-I17 -> 1.92 | O17: =C17-J17-L17 -> 1.92
... B25: trim 4 2025 | C25: 407.4 | D25: 20 | E25: 0 | F25: 0 | G25: 0 | H25: 1 | I25: =MMULT(D25:H25,K$33:K$37) -> 413.13 | J25: =K$38+K$33*D25 -> 388.48937 | K25: =C25-D25*K$33-K$38 -> 18.910625 | L25: =MMULT(E25:H25,L$34:L$37) -> 24.640625 | M25: =C25-MMULT(E25:H25,L$34:L$37) -> 382.75938 | N25: =C25-I25 -> -5.73 | O25: =C25-J25-L25 -> -5.73
B26: trim 1 2026 | N26: =SUM(N6:N25) -> 1.7053026e-13 | O26: =SUM(O6:O25) -> 1.7053026e-13
B27: trim 2 2026
B28: trim 3 2026
B29: trim 4 2026
C31: Output della funzione REGR.LIN
K32: Coeff. stimati | L32: Coeff stagionali con il vincolo di media zero
C33: {=LINEST(C6:C25,D6:H25,0,1)} -> 311.005 | D33: 288.43125 | E33: 291.6175 | F33: 254.40375 | G33: 5.10625 | J33: Trend | K33: =INDEX(C$33:G$33,1,M33) -> 5.10625 | M33: 5
C34: 3.9694859 | D34: 3.7979521 | E34: 3.6342704 | F34: 3.479549 | G34: 0.24068544 | H34: Coerff. stimati | J34: Primavera | K34: =INDEX(C$33:G$33,1,M34) -> 254.40375 | L34: =K34-AVERAGE($K$34:$K$37) -> -31.960625 | M34: 4
C35: 0.99976256 | D35: 6.0889134 | E35: #N/A | F35: #N/A | G35: #N/A | J35: Estate | K35: =INDEX(C$33:G$33,1,M35) -> 291.6175 | L35: =K35-AVERAGE($K$34:$K$37) -> 5.253125 | M35: 3
C36: 12631.865 | D36: 15 | E36: #N/A | F36: #N/A | G36: #N/A | J36: Autunno | K36: =INDEX(C$33:G$33,1,M36) -> 288.43125 | L36: =K36-AVERAGE($K$34:$K$37) -> 2.066875 | M36: 2
C37: 2341623.6 | D37: 556.123 | E37: #N/A | F37: #N/A | G37: #N/A | J37: Inverno | K37: =INDEX(C$33:G$33,1,M37) -> 311.005 | L37: =K37-AVERAGE($K$34:$K$37) -> 24.640625 | M37: 1
J38: Stima della costante | K38: =AVERAGE(K34:K37) -> 286.36437 | L38: =SUM(L33:L37) -> 5.6843419e-14

Sheet Testo_esercizio
E3: y= Andamento delle vendite di un bene (in migliaia di Euro durante il periodo I trim 2001 - 4 trim 2005)
